# 修复同步状态数据问题

## 🐛 问题描述

发现 9-1 到 9-3 的同步数据存在严重问题：

| 日期 | 状态 | 总数 | 成功 | 失败 | 问题 |
|------|------|------|------|------|------|
| 2025-09-03 | 成功 | 136 | 136 | 5,236 | ❌ 失败数远大于总数 |
| 2025-09-02 | 成功 | 746 | 746 | 4,626 | ❌ 失败数远大于总数 |
| 2025-09-01 | 成功 | 4,189 | 4,189 | 1,080 | ❌ 有失败但标记为成功 |

**根本原因**：
1. 统计逻辑错误：失败数累计错误
2. 状态判断错误：有失败记录仍标记为"成功"

---

## ✅ 已修复的代码

### 修复1：正确的状态判断逻辑

**修改文件**：`scripts/test_copy_sync.py`

```python
# 修复前（错误）：
self.update_sync_status(
    date_str, 
    'success',  # ❌ 无论有多少失败都标记为成功
    total_records=already_synced + total_inserted,
    success_count=already_synced + total_inserted,
    failed_count=failed,
    remarks=f'同步完成: 成功{success}, 失败{failed}'
)

# 修复后（正确）：
final_status = 'success' if failed == 0 else 'failed'  # ✅ 有失败就标记为失败
self.update_sync_status(
    date_str, 
    final_status, 
    total_records=actual_count,  # ✅ 总数是实际股票数
    success_count=success,       # ✅ 成功数是本次成功的数量
    failed_count=failed,         # ✅ 失败数是本次失败的数量
    remarks=f'同步完成: 成功{success}, 失败{failed}'
)
```

### 修复2：实时更新的统计逻辑

```python
# 修复前（错误）：
self.update_sync_status(
    date_str, 
    'syncing', 
    total_records=already_synced + total_inserted,  # ❌ 混淆了总数和已入库数
    success_count=already_synced + total_inserted,  # ❌ 错误的成功数
    failed_count=failed,
    remarks=f'同步中: {already_synced + total_inserted}/{actual_count}'
)

# 修复后（正确）：
self.update_sync_status(
    date_str, 
    'syncing', 
    total_records=actual_count,  # ✅ 总数是实际股票数
    success_count=success,       # ✅ 成功数是已成功获取的数量
    failed_count=failed,         # ✅ 失败数是已失败的数量
    remarks=f'同步中: {success}/{actual_count}, 失败: {failed}'
)
```

---

## 🔧 修复已有的错误数据

### 步骤1：运行修复脚本

```bash
# 设置数据库连接
export NEON_DATABASE_URL='postgresql://your-connection-string'

# 运行修复脚本
python3 scripts/fix_sync_status.py
```

### 步骤2：脚本会自动执行以下操作

1. **查找异常数据**
   - 失败数 > 0 但状态为 'success' 的记录
   - 失败数 > 总数的记录

2. **修复状态**
   - 将有失败记录的任务状态改为 'failed'
   - 询问是否重置失败数异常的记录

3. **显示统计**
   - 显示修复前后的数据对比

### 步骤3：重新同步问题日期（可选）

如果需要重新同步这些日期：

```bash
# 方法1：使用测试脚本
python3 scripts/test_copy_sync.py --date 2025-09-01 --all
python3 scripts/test_copy_sync.py --date 2025-09-02 --all
python3 scripts/test_copy_sync.py --date 2025-09-03 --all

# 方法2：使用 Web 界面
# 访问 http://localhost:3000/sync-status
# 选择日期范围并重新同步
```

---

## 📊 修复后的预期结果

### 正确的数据示例

| 日期 | 状态 | 总数 | 成功 | 失败 | 备注 |
|------|------|------|------|------|------|
| 2025-09-05 | 成功 | 5,269 | 5,269 | 0 | ✅ 全部成功 |
| 2025-09-04 | 成功 | 5,269 | 5,269 | 0 | ✅ 全部成功 |
| 2025-09-03 | 失败 | 5,372 | 136 | 5,236 | ✅ 有失败，正确标记 |
| 2025-09-02 | 失败 | 5,372 | 746 | 4,626 | ✅ 有失败，正确标记 |
| 2025-09-01 | 失败 | 5,269 | 4,189 | 1,080 | ✅ 有失败，正确标记 |

### 状态规则

- ✅ **success**: `failed_count == 0` （全部成功）
- ❌ **failed**: `failed_count > 0` （有任何失败）
- ⏭️ **skipped**: 非交易日
- 🔄 **syncing**: 正在同步中
- ⏸️ **pending**: 待同步

---

## 🎯 验证修复

### 1. 检查数据库

```sql
-- 查看所有有失败记录的任务
SELECT sync_date, status, total_records, success_count, failed_count, remarks
FROM daily_sync_status
WHERE failed_count > 0
ORDER BY sync_date DESC;

-- 应该全部是 status = 'failed'
```

### 2. 检查异常数据

```sql
-- 不应该有任何记录
SELECT sync_date, status, total_records, success_count, failed_count
FROM daily_sync_status
WHERE failed_count > 0 AND status = 'success';
```

### 3. 检查失败数异常

```sql
-- 不应该有任何记录
SELECT sync_date, status, total_records, success_count, failed_count
FROM daily_sync_status
WHERE failed_count > total_records;
```

---

## 📝 总结

### 修复内容

1. ✅ 修改 `test_copy_sync.py` 的状态判断逻辑
2. ✅ 修正统计数据的计算方式
3. ✅ 创建修复脚本 `fix_sync_status.py`
4. ✅ 提供重新同步方案

### 核心原则

**只要有任何失败，任务状态必须标记为 'failed'**

- `failed_count == 0` → `status = 'success'`
- `failed_count > 0` → `status = 'failed'`

### 后续建议

1. 运行修复脚本清理错误数据
2. 重新同步失败的日期
3. 验证新的同步任务状态正确
4. 监控后续同步任务

---

## 🔗 相关文件

- 修复的代码：`scripts/test_copy_sync.py`
- 修复脚本：`scripts/fix_sync_status.py`
- 数据库表：`daily_sync_status`
